Workbook

Sheet SCAP_Test_Matrix
K1: SCAP PT QA Status
A2: Sl No | B2: Bulletin | C2: CVE ID | D2: Description | E2: KB Article | F2: KB Article | G2: MS Risk Rating | H2: Platforms | I2: Components | J2: QA status | K2: Pass | L2: Fail | M2: NA | N2: Supported on SCAP | O2: Setup Avaialable | P2: QA Owner | Q2: Bugs | R2: Bulletins Replaced by this Update
J1048484: In progress

Sheet Assignment Summary
A1: QA | B1: # targets with component Weight = 1.5 | C1: # targets without component Weight = 1 | D1: Total (Considering weight) | E1: Test integrity of the package for:
A2: Kalyani Palada | B2: {=SUM(IF(Table1[[#This Row],[QA]]=SCAP_Test_Matrix!P$1:P$8357,1,0)*IF(SCAP_Test_Matrix!N$1:N$8357="Yes",1,0)*IF(TRIM(SCAP_Test_Matrix!I$1:I$8357)<>"",1,0)*IF(SCAP_Test_Matrix!J$1:J$8357="Slipped",0,1))} -> 0 | C2: {=SUM(IF(Table1[[#This Row],[QA]]=SCAP_Test_Matrix!P$1:P$8357,1,0)*IF(SCAP_Test_Matrix!N$1:N$8357="Yes",1,0)*IF(TRIM(SCAP_Test_Matrix!I$1:I$8357)="",1,0)*IF(SCAP_Test_Matrix!J$1:J$8357="Slipped",0,1))} -> 0 | D2: =Table1[[#This Row],['# targets with component Weight = 1.5]]*1.5+Table1[[#This Row],['# targets without component Weight = 1]]*1 -> 0
A3: Andrés Paolini | B3: {=SUM(IF(Table1[[#This Row],[QA]]=SCAP_Test_Matrix!P$1:P$8357,1,0)*IF(SCAP_Test_Matrix!N$1:N$8357="Yes",1,0)*IF(TRIM(SCAP_Test_Matrix!I$1:I$8357)<>"",1,0)*IF(SCAP_Test_Matrix!J$1:J$8357="Slipped",0,1))} -> 0 | C3: {=SUM(IF(Table1[[#This Row],[QA]]=SCAP_Test_Matrix!P$1:P$8357,1,0)*IF(SCAP_Test_Matrix!N$1:N$8357="Yes",1,0)*IF(TRIM(SCAP_Test_Matrix!I$1:I$8357)="",1,0)*IF(SCAP_Test_Matrix!J$1:J$8357="Slipped",0,1))} -> 0 | D3: =Table1[[#This Row],['# targets with component Weight = 1.5]]*1.5+Table1[[#This Row],['# targets without component Weight = 1]]*1 -> 0
A4: Isabel Betancourt | B4: {=SUM(IF(Table1[[#This Row],[QA]]=SCAP_Test_Matrix!P$1:P$8357,1,0)*IF(SCAP_Test_Matrix!N$1:N$8357="Yes",1,0)*IF(TRIM(SCAP_Test_Matrix!I$1:I$8357)<>"",1,0)*IF(SCAP_Test_Matrix!J$1:J$8357="Slipped",0,1))} -> 0 | C4: {=SUM(IF(Table1[[#This Row],[QA]]=SCAP_Test_Matrix!P$1:P$8357,1,0)*IF(SCAP_Test_Matrix!N$1:N$8357="Yes",1,0)*IF(TRIM(SCAP_Test_Matrix!I$1:I$8357)="",1,0)*IF(SCAP_Test_Matrix!J$1:J$8357="Slipped",0,1))} -> 0 | D4: =Table1[[#This Row],['# targets with component Weight = 1.5]]*1.5+Table1[[#This Row],['# targets without component Weight = 1]]*1 -> 0
A5: Felipe Anic | B5: {=SUM(IF(Table1[[#This Row],[QA]]=SCAP_Test_Matrix!P$1:P$8357,1,0)*IF(SCAP_Test_Matrix!N$1:N$8357="Yes",1,0)*IF(TRIM(SCAP_Test_Matrix!I$1:I$8357)<>"",1,0)*IF(SCAP_Test_Matrix!J$1:J$8357="Slipped",0,1))} -> 0 | C5: {=SUM(IF(Table1[[#This Row],[QA]]=SCAP_Test_Matrix!P$1:P$8357,1,0)*IF(SCAP_Test_Matrix!N$1:N$8357="Yes",1,0)*IF(TRIM(SCAP_Test_Matrix!I$1:I$8357)="",1,0)*IF(SCAP_Test_Matrix!J$1:J$8357="Slipped",0,1))} -> 0 | D5: =Table1[[#This Row],['# targets with component Weight = 1.5]]*1.5+Table1[[#This Row],['# targets without component Weight = 1]]*1 -> 0
A6: Gerardo Muñoz | B6: {=SUM(IF(Table1[[#This Row],[QA]]=SCAP_Test_Matrix!P$1:P$8357,1,0)*IF(SCAP_Test_Matrix!N$1:N$8357="Yes",1,0)*IF(TRIM(SCAP_Test_Matrix!I$1:I$8357)<>"",1,0)*IF(SCAP_Test_Matrix!J$1:J$8357="Slipped",0,1))} -> 0 | C6: {=SUM(IF(Table1[[#This Row],[QA]]=SCAP_Test_Matrix!P$1:P$8357,1,0)*IF(SCAP_Test_Matrix!N$1:N$8357="Yes",1,0)*IF(TRIM(SCAP_Test_Matrix!I$1:I$8357)="",1,0)*IF(SCAP_Test_Matrix!J$1:J$8357="Slipped",0,1))} -> 0 | D6: =Table1[[#This Row],['# targets with component Weight = 1.5]]*1.5+Table1[[#This Row],['# targets without component Weight = 1]]*1 -> 0
B7: {=SUM(IF(Table1[[#This Row],[QA]]=SCAP_Test_Matrix!P$1:P$8357,1,0)*IF(SCAP_Test_Matrix!N$1:N$8357="Yes",1,0)*IF(TRIM(SCAP_Test_Matrix!I$1:I$8357)<>"",1,0))} -> 0 | C7: {=SUM(IF(Table1[[#This Row],[QA]]=SCAP_Test_Matrix!P$1:P$8357,1,0)*IF(SCAP_Test_Matrix!N$1:N$8357="Yes",1,0)*IF(TRIM(SCAP_Test_Matrix!I$1:I$8357)="",1,0))} -> 0 | D7: =Table1[[#This Row],['# targets with component Weight = 1.5]]*1.5+Table1[[#This Row],['# targets without component Weight = 1]]*1 -> 0
A8: Total | B8: =SUBTOTAL(109,B2:B7) -> 0 | C8: =SUBTOTAL(109,C2:C7) -> 0 | D8: =SUBTOTAL(109,D2:D7) -> 0
A10: Topics pending to assign (Dev has to confirm yet if will be supported by SCAP)

Sheet QA Status
A4: Count of Bulletin | B4: QA Progress
A5: Bulletin
A6: Grand Total
A25: Supported on SCAP | B25: (blank)
A27: Bulletin | B27: Bugs ID
A28: (blank)

Sheet Sanity Test
A1: Test | B1: Description | C1: Products | D1: Performed | E1: QA status | F1: Automated | G1: Comments
A2: Benchmarks activation | B2: Activate all benchmarks available in the package, e.g. MS Windows Bulletin Benchmark <year>, Microsoft Office Patch Policy for <version>, etc. | C2: PA 5.3 | F2: Yes
C3: MNAC 3.2.1
C4: PA 6.0.1
C5: PA 6.2
A6: Backlog items in the Check Catalog | B6: Verify the oval items stored in the backlog spreadsheet within the check catalog in Policy Auditor in order to ensure that none check is being left prior to release, regarding RTW date. | C6: PA 6.0.1 | F6: Yes
A7: SCAP Test Matrix items in the Check Catalog | B7: Verify the oval items stored in the SCAP Test Matrix sheet within the check catalog in Policy Auditor in order to ensure that none check is being left prior to release (Announced by Microsoft, Adobe, among others). | C7: PA 6.0.1 | F7: No
A8: Run audit round trip of critical content | B8: Verify the execution of critical benchmarks. The Benchmarks considered for this are: Windows Bulletins 2012, Office Patch Policy (2003/2007/2010), Some Windows DISA, Windows CIS and some random CIS BM for Linux. The results have to be consistent. | C8: PA 5.3 | F8: Partially
C9: PA 6.0.1
C10: PA 6.2
C11: MVM 7.5
A12: Check in package | B12: Check in package to verify compatibility with Oval Schema and with no signing warning or errors. | C12: PA 5.3 | F12: No
C13: PA 6.0.1
C14: PA 6.2
C15: MNAC 3.2.1
C16: MVM 7.5
A17: CPE filtering | B17: Run audit round trip to ensure that the checks are filtering according to the platforms. Critical OS are: Windows 2000, Windows XP, Windows 2003, Windows Vista, Windows 2008, Windows 7, Windows 2008 R2, for both architectures: x86/x64. Red Hat 4, Red Hat 5 and Red Hat 6. | C17: PA 5.3 | F17: No
C18: PA 6.0.1
C19: PA 6.2
A20: Dropdown platform | B20: All supported platforms have to appear in platform dropdown of the ePO user interface. | C20: PA 5.3, PA 6.0.1 and PA 6.2 | F20: No
A21: New Bulletin IDs rules exist in respective benchmarks | B21: Verify that new bulletins ID rules are appended to existing benchmarks, according to the logical, e.g. Microsoft Windows Bulletins, Microsoft Office Patch Policy, etc. | C21: PA 6.0.1 | F21: Partially
A22: Windows Profiles | B22: Verify that the following benchmarks are related to the corresponding profiles, regarding platforms: | C22: PA 6.0.1 | F22: No
B23: Windows CIS Benchmark | C23: Windows 2000 - Level 1
C24: Windows 2000 Pro - Level 2
C25: Windows 2000 Srv - Level 2
C26: Windows XP - Legacy
C27: Windows XP - Enterprise - Desktop
C28: Windows XP - Enterprise - Mobile
C29: Windows XP - Specialized Security
C30: Windows Server 2003 - MS - Legacy
C31: Windows Server 2003 - MS - Enterprise
C32: Windows Server 2003 - MS - Specialized Security
C33: Windows Server 2003 - DC - Legacy
C34: Windows Server 2003 - DC - Enterprise
C35: Windows Server 2003 - DC - Specialized Security
... C47: Windows Server 2008 R2 - Specialized Security - DC
B48: Windows COBIT Benchmark | C48: Windows 2000
C49: Windows XP
C50: Windows Server 2003 - Member Server
C51: Windows Server 2003 - Domain Controller
...

Sheet Benchmark validations
A1: Benchmark | B1: Test | C1: Description | D1: Products | E1: Performed | F1: QA status | G1: Automated | H1: Comments
A2: Windows CIS Benchmark | B2: Run audit round trip for checks | C2: Run an audit to include the benchmark in order to validate the audit and finding results for every rule, which have to be consistent according to the xml code. It's necessary to take a sampling based on some criteria allowing to select a representative group of checks that can ensure the coverage and quality of the content for the sanity test. | D2: PA 6.0.1 | G2: No
D3: PA 5.3
B4: Profiles | C4: Take a sampling of the profiles to check that the external variables (Values) and the Status of the rule (Enabled and Disabled) are working as expected. | D4: PA 6.0.1 | G4: No
D5: PA 5.3
C6: Verify that the platforms listed in the profiles are consistent and that none are missing. | D6: PA 6.0.1
C7: Verify that the plarforms listed in the Affected Platforms within the xml file are correct and that none are missing. This topic needs to be verified related to the Rules section and Properties section of the benchmark. | D7: PA 6.0.1
B8: Grouping | C8: Verify that the groups related to Benchmark tree are correct and that none are missing. | D8: PA 6.0.1 | G8: No
B9: UI | C9: Verify that the user interface shown the elements correctly, such as: title, description, front-matter, rear-matter, etc when the checks and the benchmark is selected. | D9: PA 6.0.1 | G9: No
D10: PA 5.3
C11: Verify that the dropbox regarding Platform is showing the expected platforms and the filter works correctly. | D11: PA 6.0.1
D12: PA 5.3
B13: CPE filtering | C13: Run audit round trip to ensure that the checks are filtering according to the platforms mentioned in the benchmark. | D13: PA 6.0.1 | G13: No
D14: PA 5.3
B15: Check in package | C15: Check in package to verify compatibility with Oval Schema and with no signing warning or errors related to the benchmark. | D15: PA 5.3 | G15: No
D16: PA 6.0.1
D17: MNAC 3.2.1
D18: MVM 7.5
A20: Apple Mac OSX CIS Benchmark | B20: Run audit round trip for checks | C20: Run an audit to include the benchmark in order to validate the audit and finding results for every rule, which have to be consistent according to the xml code. It's necessary to take a sampling based on some criteria allowing to select a representative group of checks that can ensure the coverage and quality of the content for the sanity test. | D20: PA 6.0.1 | G20: No
D21: PA 5.3
B22: Profiles | C22: Take a sampling of the profiles to check that the external variables (Values) and the Status of the rule (Enabled and Disabled) are working as expected. | D22: PA 6.0.1 | G22: No
D23: PA 5.3
C24: Verify that the platforms listed in the profiles are consistent and that none are missing. | D24: PA 6.0.1
C25: Verify that the plarforms listed in the Affected Platforms within the xml file are correct and that none are missing. This topic needs to be verified related to the Rules section and Properties section of the benchmark. | D25: PA 6.0.1
B26: Grouping | C26: Verify that the groups related to Benchmark tree are correct and that none are missing. | D26: PA 6.0.1 | G26: No
B27: UI | C27: Verify that the user interface shown the elements correctly, such as: title, description, front-matter, rear-matter, etc when the checks and the benchmark is selected. | D27: PA 6.0.1 | G27: No
D28: PA 5.3
C29: Verify that the dropbox regarding Platform is showing the expected platforms and the filter works correctly. | D29: PA 6.0.1
D30: PA 5.3
B31: CPE filtering | C31: Run audit round trip to ensure that the checks are filtering according to the platforms mentioned in the benchmark. | D31: PA 6.0.1 | G31: No
D32: PA 5.3
B33: Check in package | C33: Check in package to verify compatibility with Oval Schema and with no signing warning or errors related to the benchmark. | D33: PA 5.3 | G33: No
D34: PA 6.0.1
D35: MNAC 3.2.1
D36: MVM 7.5
A38: Redhat Enterprise and CentOS Linux Cobit Benchmark | B38: Run audit round trip for checks | C38: Run an audit to include the benchmark in order to validate the audit and finding results for every rule, which have to be consistent according to the xml code. It's necessary to take a sampling based on some criteria allowing to select a representative group of checks that can ensure the coverage and quality of the content for the sanity test. | D38: PA 6.0.1 | G38: No
D39: PA 5.3
B40: Profiles | C40: Take a sampling of the profiles to check that the external variables (Values) and the Status of the rule (Enabled and Disabled) are working as expected. | D40: PA 6.0.1 | G40: No
D41: PA 5.3
C42: Verify that the platforms listed in the profiles are consistent and that none are missing. | D42: PA 6.0.1
...

Sheet Platform additions
A1: Added Platform | B1: Test | C1: Description | D1: Products | E1: Performed | F1: QA status | G1: Automated | H1: Comments
A2: N/A | B2: Profiles | C2: Verify that the platforms listed in the profiles are consistent and that none are missing. Besides the filter should work correctly. | D2: PA 6.0.1 | G2: No
C3: Verify that the plarforms listed in the Affected Platforms within the xml file are correct and that none are missing. This topic needs to be verified related to the Rules section and Properties section of the affected benchmarks. | D3: PA 6.0.1
B4: UI | C4: Verify that the dropbox regarding Platform is showing the expected new platform and the filter works correctly. | D4: PA 6.0.1 | G4: No
D5: PA 5.3
B6: CPE filtering | C6: Run audit round trip to ensure that the checks are filtering according to the new platform mentioned in the benchmark. | D6: PA 6.0.1 | G6: No
D7: PA 5.3
B8: Affected content | C8: Verify that all the benchmarks and checks affected by the new platform were modified to include it and is working as expected using an audit. | D8: PA 6.0.1 | G8: No
B9: Check in package | C9: Check in package to verify compatibility with Oval Schema and with no signing warning or errors related to the new platform. | D9: PA 5.3 | G9: No
D10: PA 6.0.1
D11: MNAC 3.2.1
D12: PA6.0 with MNAC 3.2.1
D13: MVM 7.5

Sheet Release readiness
A1: Process | B1: Description | C1: Item | D1: Performed | E1: QA status | F1: Automated | G1: Comments
A2: Announce that a new SCAP package will be published | B2: The SCAP & Finding packages for the <month PT/OOB> release are being tested & a posting request will be sent out within one hour. | C2: Email informing that a new package will be published | F2: No
A3: Upload SCAP and Findings Packages | B3: Post packages to the production repository. | C3: SCAP Audit package uploaded to CA-SERVER | F3: No
C4: SCAP Findings package uploaded to DALAPPDAT1
C5: Email requesting to post packages to production repository.
A6: SCAP Package Posting Notification | B6: SCAP Posting Notification email generated with PDF attached and sent to DL SITEUPDATES | C6: Email requesting to publish Release Notes. Attach PDF: McAfee Policy Auditor/McAfee NAC Content Release notes | F6: No
B7: SNS Request posted to SNS portal | C7: SNS request posted at http://serviceweb/SNS/SNS1_MainPage.aspx. | F7: No
C8: Email informing that a new SNS was created for SCAP content

Sheet Status
A1: Full Sanity Test Status
A2: Status | B2: % | C2: #
A3: In Progress | B3: =Table2[[#This Row],['#]]/SUM(Table2['#]) -> 1 | C3: {=SUM(IF('Sanity Test'!E2:E1000="",1,0)*IF('Sanity Test'!C2:C1000<>"",1,0))+SUM(IF('Benchmark validations'!F2:F1000="",1,0)*IF('Benchmark validations'!D2:D1000<>"",1,0))+SUM(IF('Platform additions'!F2:F1000="",1,0)*IF('Platform additions'!D2:D1000<>"",1,0))} -> 219
A4: OK | B4: =Table2[[#This Row],['#]]/SUM(Table2['#]) -> 0 | C4: {=SUM(IF('Sanity Test'!E2:E1000="Passed",1,0)*IF('Sanity Test'!C2:C1000<>"",1,0))+SUM(IF('Benchmark validations'!F2:F1000="Passed",1,0)*IF('Benchmark validations'!D2:D1000<>"",1,0))+SUM(IF('Platform additions'!F2:F1000="Passed",1,0)*IF('Platform additions'!D2:D1000<>"",1,0))+SUM(IF('Sanity Test'!E2:E1000="Deferred",1,0)*IF('Sanity Test'!C2:C1000<>"",1,0))+SUM(IF('Benchmark validations'!F2:F1000="Deferred",1,0)*IF('Benchmark validations'!D2:D1000<>"",1,0))+SUM(IF('Platform additions'!F2:F1000="Deferred",1,0)*IF('Platform additions'!D2:D1000<>"",1,0))+SUM(IF('Sanity Test'!E2:E1000="Not Applicable",1,0)*IF('Sanity Test'!C2:C1000<>"",1,0))+SUM(IF('Benchmark validations'!F2:F1000="Not Applicable",1,0)*IF('Benchmark validations'!D2:D1000<>"",1,0))+SUM(IF('Platform additions'!F2:F1000="Not Applicable",1,0)*IF('Platform additions'!D2:D1000<>"",1,0))} -> 0
A5: NOK | B5: =Table2[[#This Row],['#]]/SUM(Table2['#]) -> 0 | C5: {=SUM(IF('Sanity Test'!E2:E1000="Failed",1,0)*IF('Sanity Test'!C2:C1000<>"",1,0))+SUM(IF('Benchmark validations'!F2:F1000="Failed",1,0)*IF('Benchmark validations'!D2:D1000<>"",1,0))+SUM(IF('Platform additions'!F2:F1000="Failed",1,0)*IF('Platform additions'!D2:D1000<>"",1,0))} -> 0
